[ 2023-08-15 11:00:55,760 ] 187 werkzeug - INFO - [31m[1mWARNING: This is a development server. Do not use it in a production deployment. Use a production WSGI server instead.[0m
 * Running on all addresses (0.0.0.0)
 * Running on http://127.0.0.1:5000
 * Running on http://192.168.1.7:5000
[ 2023-08-15 11:00:55,760 ] 187 werkzeug - INFO - [33mPress CTRL+C to quit[0m
[ 2023-08-15 11:01:09,003 ] 187 werkzeug - INFO - 127.0.0.1 - - [15/Aug/2023 11:01:09] "GET / HTTP/1.1" 200 -
[ 2023-08-15 11:01:09,077 ] 187 werkzeug - INFO - 127.0.0.1 - - [15/Aug/2023 11:01:09] "[36mGET /static/css/index.css HTTP/1.1[0m" 304 -
[ 2023-08-15 11:01:14,658 ] 187 werkzeug - INFO - 127.0.0.1 - - [15/Aug/2023 11:01:14] "GET /predict HTTP/1.1" 200 -
[ 2023-08-15 11:01:14,668 ] 187 werkzeug - INFO - 127.0.0.1 - - [15/Aug/2023 11:01:14] "[36mGET /static/css/form.css HTTP/1.1[0m" 304 -
[ 2023-08-15 11:01:15,880 ] 187 werkzeug - INFO - 127.0.0.1 - - [15/Aug/2023 11:01:15] "[33mGET /favicon.ico HTTP/1.1[0m" 404 -
[ 2023-08-15 11:01:15,949 ] 187 werkzeug - INFO - 127.0.0.1 - - [15/Aug/2023 11:01:15] "[33mGET /favicon.ico HTTP/1.1[0m" 404 -
[ 2023-08-15 11:01:19,953 ] 1414 application - ERROR - Exception on /predict [POST]
Traceback (most recent call last):
  File "C:\Users\Vandan Maheshwari\Desktop\metro\utils.py", line 66, in load_object
    with open(file_path, "rb") as file_obj:
         ^^^^^^^^^^^^^^^^^^^^^
FileNotFoundError: [Errno 2] No such file or directory: 'src\\pipeline\\artifacts\\model.pkl'

During handling of the above exception, another exception occurred:

Traceback (most recent call last):
  File "C:\Users\Vandan Maheshwari\Desktop\metro\predict_pipeline.py", line 20, in predict
    model=load_object(file_path=model_path)
          ^^^^^^^^^^^^^^^^^^^^^^^^^^^^^^^^^
  File "C:\Users\Vandan Maheshwari\Desktop\metro\utils.py", line 70, in load_object
    raise CustomException(e, sys)
exception.CustomException: Error occured in python script name [C:\Users\Vandan Maheshwari\Desktop\metro\utils.py] line number [66] error message [[Errno 2] No such file or directory: 'src\\pipeline\\artifacts\\model.pkl']

During handling of the above exception, another exception occurred:

Traceback (most recent call last):
  File "C:\Users\Vandan Maheshwari\AppData\Local\Programs\Python\Python311\Lib\site-packages\flask\app.py", line 2190, in wsgi_app
    response = self.full_dispatch_request()
               ^^^^^^^^^^^^^^^^^^^^^^^^^^^^
  File "C:\Users\Vandan Maheshwari\AppData\Local\Programs\Python\Python311\Lib\site-packages\flask\app.py", line 1486, in full_dispatch_request
    rv = self.handle_user_exception(e)
         ^^^^^^^^^^^^^^^^^^^^^^^^^^^^^
  File "C:\Users\Vandan Maheshwari\AppData\Local\Programs\Python\Python311\Lib\site-packages\flask\app.py", line 1484, in full_dispatch_request
    rv = self.dispatch_request()
         ^^^^^^^^^^^^^^^^^^^^^^^
  File "C:\Users\Vandan Maheshwari\AppData\Local\Programs\Python\Python311\Lib\site-packages\flask\app.py", line 1469, in dispatch_request
    return self.ensure_sync(self.view_functions[rule.endpoint])(**view_args)
           ^^^^^^^^^^^^^^^^^^^^^^^^^^^^^^^^^^^^^^^^^^^^^^^^^^^^^^^^^^^^^^^^^
  File "C:\Users\Vandan Maheshwari\Desktop\metro\application.py", line 40, in predict_datapoint
    results=predict_pipeline.predict(pred_df)
            ^^^^^^^^^^^^^^^^^^^^^^^^^^^^^^^^^
  File "C:\Users\Vandan Maheshwari\Desktop\metro\predict_pipeline.py", line 28, in predict
    raise CustomException(e,sys)
exception.CustomException: Error occured in python script name [C:\Users\Vandan Maheshwari\Desktop\metro\predict_pipeline.py] line number [20] error message [Error occured in python script name [C:\Users\Vandan Maheshwari\Desktop\metro\utils.py] line number [66] error message [[Errno 2] No such file or directory: 'src\\pipeline\\artifacts\\model.pkl']]
[ 2023-08-15 11:01:19,956 ] 187 werkzeug - INFO - 127.0.0.1 - - [15/Aug/2023 11:01:19] "[35m[1mPOST /predict HTTP/1.1[0m" 500 -
